<?xml version="1.0"?>

<robot name="robot_with_wheels" xmlns:xacro="http://www.ros.org/wiki/xacro">

    <!-- ======================================================================================== -->
    <!-- XACRO VARIABLES -->
    <!-- ======================================================================================== -->

    <!-- name = that is the name of the variable-->
    <!-- value is the value the assigned inside the variable-->
    
    <xacro:property name="base_length" value="0.6">    
    </xacro:property>
    
    <xacro:property name="base_width" value="0.4">
    </xacro:property>

    <xacro:property name="base_height" value="0.2">
    </xacro:property>

    <xacro:property name="wheel_radius" value="0.12">
    </xacro:property>

    <xacro:property name="wheel_length" value="0.1">
    </xacro:property>

    <xacro:property name="head_length" value="0.05">
    </xacro:property>

    <xacro:property name="head_width" value="0.05">
    </xacro:property>

    <xacro:property name="head_height" value="0.2">
    </xacro:property>


    <!-- ======================================================================================== -->
    <!-- COLORS -->
    <!-- ======================================================================================== -->

    <material name = "blue">
        <color rgba="0 0 1 1"/>
    </material>

    <material name = "grey">
        <color rgba="0.8 0.8 0.8 1"/>
    </material>

    <material name = "green">
        <color rgba="0 1 0 1"/>
    </material>


    <!-- ======================================================================================== -->
    <!-- LINKS -->
    <!-- ======================================================================================== -->

    <!-- ROBOT BODY (BASE) -->
    <link name="base_link">
        <visual>
            <geometry>
                <box size="${base_length} ${base_width} ${base_height}"/>
            </geometry>
            <origin xyz="0 0 0.1" rpy="0 0 0"/>
            <material name="blue"/>
            
        </visual>
    </link>

    <link name="foot_link">  
    </link>

    <!-- ROBOT HEAD AT THE TOP -->
    <link name="head_link">
        <visual>
            <geometry>
                <box size="${head_length} ${head_width} ${head_height}"/>
            </geometry>
            <origin xyz="0 0 0.05" rpy="0.0 0.0 0.0"/>
            <material name="grey"/>
        </visual>
    </link>


    <!-- RIGHT BACK WHEEL -->
    <link name="right_back_wheel_link">
        <visual>
            <geometry>
                <cylinder radius="${wheel_radius}" length="${wheel_length}"/>
            </geometry>
            <origin xyz="0.0 0.0 0.0" rpy="${pi/2} 0.0 0.0"/>
            <!-- whatever put iside the ${} which is identified as xacros properties-->
            <material name="grey"/>
            
        </visual>
        
    </link>

    <!-- RIGHT FRONT WHEEL -->
    <link name="right_front_wheel_link">
        <visual>
            <geometry>
                <cylinder radius="${wheel_radius}" length="${wheel_length}"/>
            </geometry>
            <origin xyz="0.0 0.0 0.0" rpy="1.57 0.0 0.0"/>
            <material name="grey"/>
        </visual>
    </link>

    <!-- LEFT BACK WHEEL -->
    <link name="left_back_wheel_link">
        <visual>
            <geometry>
                <cylinder radius="${wheel_radius}" length="${wheel_length}"/>
            </geometry>
            <origin xyz="0 0 0" rpy="1.57 0.0 0.0"/>
            <material name="grey"/>
        </visual>
    </link>

    <!-- LEFT FRONT WHEEL -->
    <link name="left_front_wheel_link">
        <visual>
            <geometry>
                <cylinder radius="${wheel_radius}" length="${wheel_length}"/>
            </geometry>
            <origin xyz="0.0 0.0 0.0" rpy="1.57 0.0 0.0"/>
            <material name="grey"/>
        </visual>
    </link>


    <!-- ======================================================================================== -->
    <!-- JOINTS -->
    <!-- ======================================================================================== -->

    <!-- BASE AND THE HEAD JOINT -->
    <joint name="base_head" type="fixed">
        <parent link="base_link"/>
        <child link="head_link"/> 
        <origin xyz="-0.15 0 0.2" rpy="0.0 0.0 0.0"/>
        
    </joint>

    <!-- BASE AND THE RIGHT BACK WHEEL JOINT -->
    <joint name="base_right_back_wheel_link" type="continuous">
        <parent link="base_link"/>
        <child link="right_back_wheel_link"/>
        <origin xyz="0.15 0.225 0" rpy="0.0 0.0 0.0"/>
        <axis xyz="0.0 1.0 0.0"/> 
    </joint>

    <!-- BASE AND THE left BACK WHEEL JOINT -->
    <joint name="base_left_back_wheel_link" type="continuous">
        <parent link="base_link"/>
        <child link="left_back_wheel_link"/>
        <origin xyz="0.15 -0.225 0.0" rpy="0.0 0.0 0.0"/>
        <axis xyz="0.0 1.0 0.0"/> 
    </joint>


    <joint name="base_right_front_wheel_link" type="continuous">
        <parent link="base_link"/>
        <child link="right_front_wheel_link"/>
        <origin xyz="-0.15 0.225 0.0" rpy="0.0 0.0 0.0"/>
        <axis xyz="0.0 1.0 0.0"/>
        
    </joint>

    <joint name="base_left_front_wheel_link" type="continuous">
        <parent link="base_link"/>
        <child link="left_front_wheel_link"/>
        <origin xyz="-0.15 -0.225 0.0" rpy="0.0 0.0 0.0"/>
        <axis xyz="0.0 1.0 0.0"/>
    </joint>


    <joint name="base_foot_link" type="fixed">
        <parent link="base_link"/>
        <child link="foot_link"/>
        <origin xyz="0.0 0.0 -0.1" rpy="0.0 0.0 0.0"/>
        
    </joint>

</robot>
