<?xml version="1.0"?>

<robot name="robot_with_wheels">

    <material name = "blue">
        <color rgba="0 0 1 0.5"/>
    </material>

    <material name = "grey">
        <color rgba="0.8 0.8 0.8 1"/>
    </material>

    <material name = "green">
        <color rgba="0 1 0 1"/>
    </material>


    <!-- ROBOT BODY (BASE) -->
    <link name="base_link">
        <visual>
            <geometry>
                <box size="0.6 0.4 0.2"/>
            </geometry>
            <origin xyz="0 0 0.1" rpy="0 0 0"/>
            <material name="blue"/>
            
        </visual>
    </link>

    <link name="foot_link">  
    </link>

    <!-- ROBOT HEAD AT THE TOP -->
    <link name="head_link">
        <visual>
            <geometry>
                <box size="0.05 0.05 0.1"/>
            </geometry>
            <origin xyz="0 0 0.05" rpy="0.0 0.0 0.0"/>
            <material name="blue"/>
        </visual>
    </link>


    <!-- RIGHT BACK WHEEL -->
    <link name="right_back_wheel_link">
        <visual>
            <geometry>
                <cylinder radius="0.1" length="0.05"/>
            </geometry>
            <origin xyz="0.0 0.0 0.0" rpy="1.57 0.0 0.0"/>
            <material name="grey"/>
            
        </visual>
        
    </link>

    <!-- RIGHT FRONT WHEEL -->
    <link name="right_front_wheel_link">
        <visual>
            <geometry>
                <cylinder radius="0.1" length="0.05"/>
            </geometry>
            <origin xyz="0.0 0.0 0.0" rpy="1.57 0.0 0.0"/>
            <material name="grey"/>
        </visual>
    </link>

    <!-- LEFT BACK WHEEL -->
    <link name="left_back_wheel_link">
        <visual>
            <geometry>
                <cylinder radius="0.1" length="0.05"/>
            </geometry>
            <origin xyz="0 0 0" rpy="1.57 0.0 0.0"/>
            <material name="grey"/>
        </visual>
    </link>

    <!-- LEFT FRONT WHEEL -->
    <link name="left_front_wheel_link">
        <visual>
            <geometry>
                <cylinder radius="0.1" length="0.05"/>
            </geometry>
            <origin xyz="0.0 0.0 0.0" rpy="1.57 0.0 0.0"/>
            <material name="grey"/>
        </visual>
    </link>


    <!-- BASE AND THE HEAD JOINT -->
    <joint name="base_head" type="fixed">
        <parent link="base_link"/>
        <child link="head_link"/> 
        <origin xyz="-0.15 0 0.2" rpy="0.0 0.0 0.0"/>
        
    </joint>

    <!-- BASE AND THE RIGHT BACK WHEEL JOINT -->
    <joint name="base_right_back_wheel_link" type="continuous">
        <parent link="base_link"/>
        <child link="right_back_wheel_link"/>
        <origin xyz="0.15 0.225 0" rpy="0.0 0.0 0.0"/>
        <axis xyz="0.0 1.0 0.0"/> 
    </joint>

    <!-- BASE AND THE left BACK WHEEL JOINT -->
    <joint name="base_left_back_wheel_link" type="continuous">
        <parent link="base_link"/>
        <child link="left_back_wheel_link"/>
        <origin xyz="0.15 -0.225 0.0" rpy="0.0 0.0 0.0"/>
        <axis xyz="0.0 1.0 0.0"/> 
    </joint>


    <joint name="base_right_front_wheel_link" type="continuous">
        <parent link="base_link"/>
        <child link="right_front_wheel_link"/>
        <origin xyz="-0.15 0.225 0.0" rpy="0.0 0.0 0.0"/>
        <axis xyz="0.0 1.0 0.0"/>
        
    </joint>

    <joint name="base_left_front_wheel_link" type="continuous">
        <parent link="base_link"/>
        <child link="left_front_wheel_link"/>
        <origin xyz="-0.15 -0.225 0.0" rpy="0.0 0.0 0.0"/>
        <axis xyz="0.0 1.0 0.0"/>
    </joint>


    <joint name="base_foot_link" type="fixed">
        <parent link="base_link"/>
        <child link="foot_link"/>
        <origin xyz="0.0 0.0 -0.1" rpy="0.0 0.0 0.0"/>
        
    </joint>

</robot>
